Workbook

Sheet 0. 표지
K3: 문서번호
K4: 작성자
K5: 보안등급
K6: Ver
B11: "제로데이클리닉" 취약점 진단
B13: 서버 진단 상세결과

Sheet 1. 진단 대상
B1: ※ 진단 대상 리스트 - 서버 2대 (Windows 2대)
B2: 순번 | C2: 진단 대상 | G2: 비고
C3: Hostname | D3: IP Address | E3: 버전정보 | F3: 용도
B4: Windows

Sheet 2-1. 요약결과(그래프)
B2: ※ 대상별 평균 점수 그래프
B4: 진단 대상 | C4: 평균 | D4: 수량
B5: 총 평균 | C5: =IFERROR(AVERAGE('2-2. 요약 진단결과(Window)'!$F$71:$G$71),"") | D5: =D6
B6: Windows | C6: =IFERROR(AVERAGE('2-2. 요약 진단결과(Window)'!$F$71:$G$71),"") | D6: =COUNT('1. 진단 대상'!$B$5:$B$6)
B17: 전체 | D17: =COUNT('1. 진단 대상'!$B$5:$B$6)
B18: 안전(85이상) | C18: =IF($D$17=0,0,D18/$D$17) | D18: =COUNTIF('2-2. 요약 진단결과(Window)'!$F$71:$G$71,">=0.85")
B19: 양호(70~85미만) | C19: =IF($D$17=0,0,D19/$D$17) | D19: =COUNTIFS('2-2. 요약 진단결과(Window)'!$F$71:$G$71,">=0.7",'2-2. 요약 진단결과(Window)'!$F$71:$G$71,"<0.85")
B20: 취약(70미만) | C20: =IF($D$17=0,0,D20/$D$17) | D20: =COUNTIF('2-2. 요약 진단결과(Window)'!$F$71:$G$71,"<0.7")
V34: Windows
V35: NO. | W35: Hostname | X35: 점수
V36: 1 | W36: =IFERROR(VLOOKUP($V36,'1. 진단 대상'!$B$5:$F$6,2,FALSE),"") | X36: =IFERROR(HLOOKUP($V36,'2-2. 요약 진단결과(Window)'!$F$3:$G$71,69,FALSE),"")
V37: 2 | W37: =IFERROR(VLOOKUP($V37,'1. 진단 대상'!$B$5:$F$6,2,FALSE),"") | X37: =IFERROR(HLOOKUP($V37,'2-2. 요약 진단결과(Window)'!$F$3:$G$71,69,FALSE),"")
V38: 3 | W38: =IFERROR(VLOOKUP($V38,'1. 진단 대상'!$B$5:$F$6,2,FALSE),"") | X38: =IFERROR(HLOOKUP($V38,'2-2. 요약 진단결과(Window)'!$F$3:$G$71,69,FALSE),"")
V39: 4 | W39: =IFERROR(VLOOKUP($V39,'1. 진단 대상'!$B$5:$F$6,2,FALSE),"") | X39: =IFERROR(HLOOKUP($V39,'2-2. 요약 진단결과(Window)'!$F$3:$G$71,69,FALSE),"")
V40: 5 | W40: =IFERROR(VLOOKUP($V40,'1. 진단 대상'!$B$5:$F$6,2,FALSE),"") | X40: =IFERROR(HLOOKUP($V40,'2-2. 요약 진단결과(Window)'!$F$3:$G$71,69,FALSE),"")
V41: 6 | W41: =IFERROR(VLOOKUP($V41,'1. 진단 대상'!$B$5:$F$6,2,FALSE),"") | X41: =IFERROR(HLOOKUP($V41,'2-2. 요약 진단결과(Window)'!$F$3:$G$71,69,FALSE),"")
V42: 7 | W42: =IFERROR(VLOOKUP($V42,'1. 진단 대상'!$B$5:$F$6,2,FALSE),"") | X42: =IFERROR(HLOOKUP($V42,'2-2. 요약 진단결과(Window)'!$F$3:$G$71,69,FALSE),"")
V43: 8 | W43: =IFERROR(VLOOKUP($V43,'1. 진단 대상'!$B$5:$F$6,2,FALSE),"") | X43: =IFERROR(HLOOKUP($V43,'2-2. 요약 진단결과(Window)'!$F$3:$G$71,69,FALSE),"")
V44: 9 | W44: =IFERROR(VLOOKUP($V44,'1. 진단 대상'!$B$5:$F$6,2,FALSE),"") | X44: =IFERROR(HLOOKUP($V44,'2-2. 요약 진단결과(Window)'!$F$3:$G$71,69,FALSE),"")
V45: 10 | W45: =IFERROR(VLOOKUP($V45,'1. 진단 대상'!$B$5:$F$6,2,FALSE),"") | X45: =IFERROR(HLOOKUP($V45,'2-2. 요약 진단결과(Window)'!$F$3:$G$71,69,FALSE),"")
V46: 11 | W46: =IFERROR(VLOOKUP($V46,'1. 진단 대상'!$B$5:$F$6,2,FALSE),"") | X46: =IFERROR(HLOOKUP($V46,'2-2. 요약 진단결과(Window)'!$F$3:$G$71,69,FALSE),"")
V47: 12 | W47: =IFERROR(VLOOKUP($V47,'1. 진단 대상'!$B$5:$F$6,2,FALSE),"") | X47: =IFERROR(HLOOKUP($V47,'2-2. 요약 진단결과(Window)'!$F$3:$G$71,69,FALSE),"")
... V50: 15 | W50: =IFERROR(VLOOKUP($V50,'1. 진단 대상'!$B$5:$F$6,2,FALSE),"") | X50: =IFERROR(HLOOKUP($V50,'2-2. 요약 진단결과(Window)'!$F$3:$G$71,69,FALSE),"")
B71: 진단 도메인 | C71: 평균 점수 | D71: 총 평균
B72: =SUBSTITUTE('2-2. 요약 진단결과(Window)'!B6,CHAR(10),"") | C72: ='2-2. 요약 진단결과(Window)'!I6 | D72: =$C$6 | BA72: =IF(ISNUMBER(C72),C72,NA()) | BB72: =IF(ISNUMBER(D72),D72,NA())
B73: =SUBSTITUTE('2-2. 요약 진단결과(Window)'!B20,CHAR(10),"") | C73: ='2-2. 요약 진단결과(Window)'!I20 | D73: =$C$6 | BA73: =IF(ISNUMBER(C73),C73,NA()) | BB73: =IF(ISNUMBER(D73),D73,NA())
B74: =SUBSTITUTE('2-2. 요약 진단결과(Window)'!B43,CHAR(10),"") | C74: ='2-2. 요약 진단결과(Window)'!I43 | D74: =$C$6 | BA74: =IF(ISNUMBER(C74),C74,NA()) | BB74: =IF(ISNUMBER(D74),D74,NA())
B75: =SUBSTITUTE('2-2. 요약 진단결과(Window)'!B45,CHAR(10),"") | C75: ='2-2. 요약 진단결과(Window)'!I45 | D75: =$C$6 | BA75: =IF(ISNUMBER(C75),C75,NA()) | BB75: =IF(ISNUMBER(D75),D75,NA())
B76: =SUBSTITUTE('2-2. 요약 진단결과(Window)'!B49,CHAR(10),"") | C76: ='2-2. 요약 진단결과(Window)'!I49 | D76: =$C$6 | BA76: =IF(ISNUMBER(C76),C76,NA()) | BB76: =IF(ISNUMBER(D76),D76,NA())

Sheet 2-2. 요약 진단결과(Window)
B2: Windows 서버 취약점 진단 요약결과(64항목)
B3: 진단항목 | C3: No. | D3: 세부진단항목 | E3: 중요도 | F3: 1 | G3: 2
F4: =IFERROR(VLOOKUP(F$3,'1. 진단 대상'!$B$5:$F$6,2,FALSE),"") | G4: =IFERROR(VLOOKUP(G$3,'1. 진단 대상'!$B$5:$F$6,2,FALSE),"")
F5: =IFERROR(VLOOKUP(F$3,'1. 진단 대상'!$B$5:$F$6,3,FALSE),"") | G5: =IFERROR(VLOOKUP(G$3,'1. 진단 대상'!$B$5:$F$6,3,FALSE),"") | I5: 영역별점수 | J5: 점수 | K5: 양호 | L5: 취약 | M5: N/A
B6: 1. 계정 관리 | C6: W-01 | D6: Administrator 계정 이름 변경 등 보안성 강화 | E6: 상 | F6: =IFERROR(T(HLOOKUP(F$3,'3-1. 진단 결과(window)'!$F$3:$I$69,ROW(A4),FALSE)),"") | G6: =IFERROR(T(HLOOKUP(G$3,'3-1. 진단 결과(window)'!$F$3:$I$69,ROW(A4),FALSE)),"") | I6: =IF(COUNTIF(J6:J19,"N/A")=COUNTA(J6:J19),"N/A",AVERAGE(J6:J19)) | J6: =IF($K6+$L6=0,"N/A",$K6/($K6+$L6)) | K6: =COUNTIF($F6:$G6,"양호") | L6: =COUNTIF($F6:$G6,"취약") | M6: =COUNTIF($F6:$G6,"N/A")
C7: W-02 | D7: Guest 계정 비활성화 | E7: 상 | F7: =IFERROR(T(HLOOKUP(F$3,'3-1. 진단 결과(window)'!$F$3:$I$69,ROW(A5),FALSE)),"") | G7: =IFERROR(T(HLOOKUP(G$3,'3-1. 진단 결과(window)'!$F$3:$I$69,ROW(A5),FALSE)),"") | J7: =IF($K7+$L7=0,"N/A",$K7/($K7+$L7)) | K7: =COUNTIF($F7:$G7,"양호") | L7: =COUNTIF($F7:$G7,"취약") | M7: =COUNTIF($F7:$G7,"N/A")
C8: W-03 | D8: 불필요한 계정 제거 | E8: 상 | F8: =IFERROR(T(HLOOKUP(F$3,'3-1. 진단 결과(window)'!$F$3:$I$69,ROW(A6),FALSE)),"") | G8: =IFERROR(T(HLOOKUP(G$3,'3-1. 진단 결과(window)'!$F$3:$I$69,ROW(A6),FALSE)),"") | J8: =IF($K8+$L8=0,"N/A",$K8/($K8+$L8)) | K8: =COUNTIF($F8:$G8,"양호") | L8: =COUNTIF($F8:$G8,"취약") | M8: =COUNTIF($F8:$G8,"N/A")
C9: W-04 | D9: 계정 잠금 임계값 설정 | E9: 상 | F9: =IFERROR(T(HLOOKUP(F$3,'3-1. 진단 결과(window)'!$F$3:$I$69,ROW(A7),FALSE)),"") | G9: =IFERROR(T(HLOOKUP(G$3,'3-1. 진단 결과(window)'!$F$3:$I$69,ROW(A7),FALSE)),"") | J9: =IF($K9+$L9=0,"N/A",$K9/($K9+$L9)) | K9: =COUNTIF($F9:$G9,"양호") | L9: =COUNTIF($F9:$G9,"취약") | M9: =COUNTIF($F9:$G9,"N/A")
C10: W-05 | D10: 해독 가능한 암호화를 사용하여 암호 저장 해제 | E10: 상 | F10: =IFERROR(T(HLOOKUP(F$3,'3-1. 진단 결과(window)'!$F$3:$I$69,ROW(A8),FALSE)),"") | G10: =IFERROR(T(HLOOKUP(G$3,'3-1. 진단 결과(window)'!$F$3:$I$69,ROW(A8),FALSE)),"") | J10: =IF($K10+$L10=0,"N/A",$K10/($K10+$L10)) | K10: =COUNTIF($F10:$G10,"양호") | L10: =COUNTIF($F10:$G10,"취약") | M10: =COUNTIF($F10:$G10,"N/A")
C11: W-06 | D11: 관리자 그룹에 최소한의 사용자 포함 | E11: 상 | F11: =IFERROR(T(HLOOKUP(F$3,'3-1. 진단 결과(window)'!$F$3:$I$69,ROW(A9),FALSE)),"") | G11: =IFERROR(T(HLOOKUP(G$3,'3-1. 진단 결과(window)'!$F$3:$I$69,ROW(A9),FALSE)),"") | J11: =IF($K11+$L11=0,"N/A",$K11/($K11+$L11)) | K11: =COUNTIF($F11:$G11,"양호") | L11: =COUNTIF($F11:$G11,"취약") | M11: =COUNTIF($F11:$G11,"N/A")
C12: W-07 | D12: Everyone 사용 권한을 익명 사용자에게 적용 | E12: 중 | F12: =IFERROR(T(HLOOKUP(F$3,'3-1. 진단 결과(window)'!$F$3:$I$69,ROW(A10),FALSE)),"") | G12: =IFERROR(T(HLOOKUP(G$3,'3-1. 진단 결과(window)'!$F$3:$I$69,ROW(A10),FALSE)),"") | J12: =IF($K12+$L12=0,"N/A",$K12/($K12+$L12)) | K12: =COUNTIF($F12:$G12,"양호") | L12: =COUNTIF($F12:$G12,"취약") | M12: =COUNTIF($F12:$G12,"N/A")
C13: W-08 | D13: 계정 잠금 기간 설정 | E13: 중 | F13: =IFERROR(T(HLOOKUP(F$3,'3-1. 진단 결과(window)'!$F$3:$I$69,ROW(A11),FALSE)),"") | G13: =IFERROR(T(HLOOKUP(G$3,'3-1. 진단 결과(window)'!$F$3:$I$69,ROW(A11),FALSE)),"") | J13: =IF($K13+$L13=0,"N/A",$K13/($K13+$L13)) | K13: =COUNTIF($F13:$G13,"양호") | L13: =COUNTIF($F13:$G13,"취약") | M13: =COUNTIF($F13:$G13,"N/A")
C14: W-09 | D14: 비밀번호 관리정책 설정 | E14: 상 | F14: =IFERROR(T(HLOOKUP(F$3,'3-1. 진단 결과(window)'!$F$3:$I$69,ROW(A12),FALSE)),"") | G14: =IFERROR(T(HLOOKUP(G$3,'3-1. 진단 결과(window)'!$F$3:$I$69,ROW(A12),FALSE)),"") | J14: =IF($K14+$L14=0,"N/A",$K14/($K14+$L14)) | K14: =COUNTIF($F14:$G14,"양호") | L14: =COUNTIF($F14:$G14,"취약") | M14: =COUNTIF($F14:$G14,"N/A")
C15: W-10 | D15: 마지막 사용자 이름 표시 안 함 | E15: 중 | F15: =IFERROR(T(HLOOKUP(F$3,'3-1. 진단 결과(window)'!$F$3:$I$69,ROW(A13),FALSE)),"") | G15: =IFERROR(T(HLOOKUP(G$3,'3-1. 진단 결과(window)'!$F$3:$I$69,ROW(A13),FALSE)),"") | J15: =IF($K15+$L15=0,"N/A",$K15/($K15+$L15)) | K15: =COUNTIF($F15:$G15,"양호") | L15: =COUNTIF($F15:$G15,"취약") | M15: =COUNTIF($F15:$G15,"N/A")
C16: W-11 | D16: 로컬 로그온 허용 | E16: 중 | F16: =IFERROR(T(HLOOKUP(F$3,'3-1. 진단 결과(window)'!$F$3:$I$69,ROW(A14),FALSE)),"") | G16: =IFERROR(T(HLOOKUP(G$3,'3-1. 진단 결과(window)'!$F$3:$I$69,ROW(A14),FALSE)),"") | J16: =IF($K16+$L16=0,"N/A",$K16/($K16+$L16)) | K16: =COUNTIF($F16:$G16,"양호") | L16: =COUNTIF($F16:$G16,"취약") | M16: =COUNTIF($F16:$G16,"N/A")
C17: W-12 | D17: 익명 SID/이름 변환 허용 해제 | E17: 중 | F17: =IFERROR(T(HLOOKUP(F$3,'3-1. 진단 결과(window)'!$F$3:$I$69,ROW(A15),FALSE)),"") | G17: =IFERROR(T(HLOOKUP(G$3,'3-1. 진단 결과(window)'!$F$3:$I$69,ROW(A15),FALSE)),"") | J17: =IF($K17+$L17=0,"N/A",$K17/($K17+$L17)) | K17: =COUNTIF($F17:$G17,"양호") | L17: =COUNTIF($F17:$G17,"취약") | M17: =COUNTIF($F17:$G17,"N/A")
C18: W-13 | D18: 콘솔 로그온 시 로컬 계정에서 빈 암호 사용 제한 | E18: 중 | F18: =IFERROR(T(HLOOKUP(F$3,'3-1. 진단 결과(window)'!$F$3:$I$69,ROW(A16),FALSE)),"") | G18: =IFERROR(T(HLOOKUP(G$3,'3-1. 진단 결과(window)'!$F$3:$I$69,ROW(A16),FALSE)),"") | J18: =IF($K18+$L18=0,"N/A",$K18/($K18+$L18)) | K18: =COUNTIF($F18:$G18,"양호") | L18: =COUNTIF($F18:$G18,"취약") | M18: =COUNTIF($F18:$G18,"N/A")
C19: W-14 | D19: 원격터미널 접속 가능한 사용자 그룹 제한 | E19: 중 | F19: =IFERROR(T(HLOOKUP(F$3,'3-1. 진단 결과(window)'!$F$3:$I$69,ROW(A17),FALSE)),"") | G19: =IFERROR(T(HLOOKUP(G$3,'3-1. 진단 결과(window)'!$F$3:$I$69,ROW(A17),FALSE)),"") | J19: =IF($K19+$L19=0,"N/A",$K19/($K19+$L19)) | K19: =COUNTIF($F19:$G19,"양호") | L19: =COUNTIF($F19:$G19,"취약") | M19: =COUNTIF($F19:$G19,"N/A")
B20: 2. 서비스 관리 | C20: W-15 | D20: 사용자 개인키 사용 시 암호 입력 | E20: 상 | F20: =IFERROR(T(HLOOKUP(F$3,'3-1. 진단 결과(window)'!$F$3:$I$69,ROW(A18),FALSE)),"") | G20: =IFERROR(T(HLOOKUP(G$3,'3-1. 진단 결과(window)'!$F$3:$I$69,ROW(A18),FALSE)),"") | I20: =IF(COUNTIF(J20:J42,"N/A")=COUNTA(J20:J42),"N/A",AVERAGE(J20:J42)) | J20: =IF($K20+$L20=0,"N/A",$K20/($K20+$L20)) | K20: =COUNTIF($F20:$G20,"양호") | L20: =COUNTIF($F20:$G20,"취약") | M20: =COUNTIF($F20:$G20,"N/A")
C21: W-16 | D21: 공유 권한 및 사용자 그룹 설정 | E21: 상 | F21: =IFERROR(T(HLOOKUP(F$3,'3-1. 진단 결과(window)'!$F$3:$I$69,ROW(A19),FALSE)),"") | G21: =IFERROR(T(HLOOKUP(G$3,'3-1. 진단 결과(window)'!$F$3:$I$69,ROW(A19),FALSE)),"") | J21: =IF($K21+$L21=0,"N/A",$K21/($K21+$L21)) | K21: =COUNTIF($F21:$G21,"양호") | L21: =COUNTIF($F21:$G21,"취약") | M21: =COUNTIF($F21:$G21,"N/A")
C22: W-17 | D22: 하드디스크 기본 공유 제거 | E22: 상 | F22: =IFERROR(T(HLOOKUP(F$3,'3-1. 진단 결과(window)'!$F$3:$I$69,ROW(A20),FALSE)),"") | G22: =IFERROR(T(HLOOKUP(G$3,'3-1. 진단 결과(window)'!$F$3:$I$69,ROW(A20),FALSE)),"") | J22: =IF($K22+$L22=0,"N/A",$K22/($K22+$L22)) | K22: =COUNTIF($F22:$G22,"양호") | L22: =COUNTIF($F22:$G22,"취약") | M22: =COUNTIF($F22:$G22,"N/A")
C23: W-18 | D23: 불필요한 서비스 제거 | E23: 상 | F23: =IFERROR(T(HLOOKUP(F$3,'3-1. 진단 결과(window)'!$F$3:$I$69,ROW(A21),FALSE)),"") | G23: =IFERROR(T(HLOOKUP(G$3,'3-1. 진단 결과(window)'!$F$3:$I$69,ROW(A21),FALSE)),"") | J23: =IF($K23+$L23=0,"N/A",$K23/($K23+$L23)) | K23: =COUNTIF($F23:$G23,"양호") | L23: =COUNTIF($F23:$G23,"취약") | M23: =COUNTIF($F23:$G23,"N/A")
C24: W-19 | D24: 불필요한 IIS 서비스 구동 점검 | E24: 상 | F24: =IFERROR(T(HLOOKUP(F$3,'3-1. 진단 결과(window)'!$F$3:$I$69,ROW(A22),FALSE)),"") | G24: =IFERROR(T(HLOOKUP(G$3,'3-1. 진단 결과(window)'!$F$3:$I$69,ROW(A22),FALSE)),"") | J24: =IF($K24+$L24=0,"N/A",$K24/($K24+$L24)) | K24: =COUNTIF($F24:$G24,"양호") | L24: =COUNTIF($F24:$G24,"취약") | M24: =COUNTIF($F24:$G24,"N/A")
C25: W-20 | D25: NetBIOS 바인딩 서비스 구동 점검 | E25: 상 | F25: =IFERROR(T(HLOOKUP(F$3,'3-1. 진단 결과(window)'!$F$3:$I$69,ROW(A23),FALSE)),"") | G25: =IFERROR(T(HLOOKUP(G$3,'3-1. 진단 결과(window)'!$F$3:$I$69,ROW(A23),FALSE)),"") | J25: =IF($K25+$L25=0,"N/A",$K25/($K25+$L25)) | K25: =COUNTIF($F25:$G25,"양호") | L25: =COUNTIF($F25:$G25,"취약") | M25: =COUNTIF($F25:$G25,"N/A")
C26: W-21 | D26: 암호화되지 않는 FTP 서비스 비활성화 | E26: 상 | F26: =IFERROR(T(HLOOKUP(F$3,'3-1. 진단 결과(window)'!$F$3:$I$69,ROW(A24),FALSE)),"") | G26: =IFERROR(T(HLOOKUP(G$3,'3-1. 진단 결과(window)'!$F$3:$I$69,ROW(A24),FALSE)),"") | J26: =IF($K26+$L26=0,"N/A",$K26/($K26+$L26)) | K26: =COUNTIF($F26:$G26,"양호") | L26: =COUNTIF($F26:$G26,"취약") | M26: =COUNTIF($F26:$G26,"N/A")
C27: W-22 | D27: FTP 디렉토리 접근권한 설정 | E27: 상 | F27: =IFERROR(T(HLOOKUP(F$3,'3-1. 진단 결과(window)'!$F$3:$I$69,ROW(A25),FALSE)),"") | G27: =IFERROR(T(HLOOKUP(G$3,'3-1. 진단 결과(window)'!$F$3:$I$69,ROW(A25),FALSE)),"") | J27: =IF($K27+$L27=0,"N/A",$K27/($K27+$L27)) | K27: =COUNTIF($F27:$G27,"양호") | L27: =COUNTIF($F27:$G27,"취약") | M27: =COUNTIF($F27:$G27,"N/A")
C28: W-23 | D28: 공유 서비스에 대한 익명 접근 제한 설정 | E28: 상 | F28: =IFERROR(T(HLOOKUP(F$3,'3-1. 진단 결과(window)'!$F$3:$I$69,ROW(A26),FALSE)),"") | G28: =IFERROR(T(HLOOKUP(G$3,'3-1. 진단 결과(window)'!$F$3:$I$69,ROW(A26),FALSE)),"") | J28: =IF($K28+$L28=0,"N/A",$K28/($K28+$L28)) | K28: =COUNTIF($F28:$G28,"양호") | L28: =COUNTIF($F28:$G28,"취약") | M28: =COUNTIF($F28:$G28,"N/A")
C29: W-24 | D29: FTP 접근 제어 설정 | E29: 상 | F29: =IFERROR(T(HLOOKUP(F$3,'3-1. 진단 결과(window)'!$F$3:$I$69,ROW(A27),FALSE)),"") | G29: =IFERROR(T(HLOOKUP(G$3,'3-1. 진단 결과(window)'!$F$3:$I$69,ROW(A27),FALSE)),"") | J29: =IF($K29+$L29=0,"N/A",$K29/($K29+$L29)) | K29: =COUNTIF($F29:$G29,"양호") | L29: =COUNTIF($F29:$G29,"취약") | M29: =COUNTIF($F29:$G29,"N/A")
C30: W-25 | D30: DNS Zone Transfer 설정 | E30: 상 | F30: =IFERROR(T(HLOOKUP(F$3,'3-1. 진단 결과(window)'!$F$3:$I$69,ROW(A28),FALSE)),"") | G30: =IFERROR(T(HLOOKUP(G$3,'3-1. 진단 결과(window)'!$F$3:$I$69,ROW(A28),FALSE)),"") | J30: =IF($K30+$L30=0,"N/A",$K30/($K30+$L30)) | K30: =COUNTIF($F30:$G30,"양호") | L30: =COUNTIF($F30:$G30,"취약") | M30: =COUNTIF($F30:$G30,"N/A")
C31: W-26 | D31: RDS(Remote Data Services) 제거 | E31: 상 | F31: =IFERROR(T(HLOOKUP(F$3,'3-1. 진단 결과(window)'!$F$3:$I$69,ROW(A29),FALSE)),"") | G31: =IFERROR(T(HLOOKUP(G$3,'3-1. 진단 결과(window)'!$F$3:$I$69,ROW(A29),FALSE)),"") | J31: =IF($K31+$L31=0,"N/A",$K31/($K31+$L31)) | K31: =COUNTIF($F31:$G31,"양호") | L31: =COUNTIF($F31:$G31,"취약") | M31: =COUNTIF($F31:$G31,"N/A")
C32: W-27 | D32: 최신 Windows OS Build 버전 적용 | E32: 상 | F32: =IFERROR(T(HLOOKUP(F$3,'3-1. 진단 결과(window)'!$F$3:$I$69,ROW(A30),FALSE)),"") | G32: =IFERROR(T(HLOOKUP(G$3,'3-1. 진단 결과(window)'!$F$3:$I$69,ROW(A30),FALSE)),"") | J32: =IF($K32+$L32=0,"N/A",$K32/($K32+$L32)) | K32: =COUNTIF($F32:$G32,"양호") | L32: =COUNTIF($F32:$G32,"취약") | M32: =COUNTIF($F32:$G32,"N/A")
... C42: W-37 | D42: 예약된 작업에 의심스러운 명령이 등록되어 있는지 점검 | E42: 중 | F42: =IFERROR(T(HLOOKUP(F$3,'3-1. 진단 결과(window)'!$F$3:$I$69,ROW(A40),FALSE)),"") | G42: =IFERROR(T(HLOOKUP(G$3,'3-1. 진단 결과(window)'!$F$3:$I$69,ROW(A40),FALSE)),"") | J42: =IF($K42+$L42=0,"N/A",$K42/($K42+$L42)) | K42: =COUNTIF($F42:$G42,"양호") | L42: =COUNTIF($F42:$G42,"취약") | M42: =COUNTIF($F42:$G42,"N/A")
B43: 3. 패치 관리 | C43: W-38 | D43: 주기적 보안 패치 및 벤더 권고사항 적용 | E43: 상 | F43: =IFERROR(T(HLOOKUP(F$3,'3-1. 진단 결과(window)'!$F$3:$I$69,ROW(A41),FALSE)),"") | G43: =IFERROR(T(HLOOKUP(G$3,'3-1. 진단 결과(window)'!$F$3:$I$69,ROW(A41),FALSE)),"") | I43: =IF(COUNTIF(J43:J44,"N/A")=COUNTA(J43:J44),"N/A",AVERAGE(J43:J44)) | J43: =IF($K43+$L43=0,"N/A",$K43/($K43+$L43)) | K43: =COUNTIF($F43:$G43,"양호") | L43: =COUNTIF($F43:$G43,"취약") | M43: =COUNTIF($F43:$G43,"N/A")
C44: W-39 | D44: 백신 프로그램 업데이트 | E44: 상 | F44: =IFERROR(T(HLOOKUP(F$3,'3-1. 진단 결과(window)'!$F$3:$I$69,ROW(A42),FALSE)),"") | G44: =IFERROR(T(HLOOKUP(G$3,'3-1. 진단 결과(window)'!$F$3:$I$69,ROW(A42),FALSE)),"") | J44: =IF($K44+$L44=0,"N/A",$K44/($K44+$L44)) | K44: =COUNTIF($F44:$G44,"양호") | L44: =COUNTIF($F44:$G44,"취약") | M44: =COUNTIF($F44:$G44,"N/A")
B45: 4. 로그 관리 | C45: W-40 | D45: 정책에 따른 시스템 로깅 설정 | E45: 중 | F45: =IFERROR(T(HLOOKUP(F$3,'3-1. 진단 결과(window)'!$F$3:$I$69,ROW(A43),FALSE)),"") | G45: =IFERROR(T(HLOOKUP(G$3,'3-1. 진단 결과(window)'!$F$3:$I$69,ROW(A43),FALSE)),"") | I45: =IF(COUNTIF(J45:J48,"N/A")=COUNTA(J45:J48),"N/A",AVERAGE(J45:J48)) | J45: =IF($K45+$L45=0,"N/A",$K45/($K45+$L45)) | K45: =COUNTIF($F45:$G45,"양호") | L45: =COUNTIF($F45:$G45,"취약") | M45: =COUNTIF($F45:$G45,"N/A")
C46: W-41 | D46: NTP 및 시각 동기화 설정 | E46: 중 | F46: =IFERROR(T(HLOOKUP(F$3,'3-1. 진단 결과(window)'!$F$3:$I$69,ROW(A44),FALSE)),"") | G46: =IFERROR(T(HLOOKUP(G$3,'3-1. 진단 결과(window)'!$F$3:$I$69,ROW(A44),FALSE)),"") | J46: =IF($K46+$L46=0,"N/A",$K46/($K46+$L46)) | K46: =COUNTIF($F46:$G46,"양호") | L46: =COUNTIF($F46:$G46,"취약") | M46: =COUNTIF($F46:$G46,"N/A")
C47: W-42 | D47: 이벤트 로그 관리 설정 | E47: 하 | F47: =IFERROR(T(HLOOKUP(F$3,'3-1. 진단 결과(window)'!$F$3:$I$69,ROW(A45),FALSE)),"") | G47: =IFERROR(T(HLOOKUP(G$3,'3-1. 진단 결과(window)'!$F$3:$I$69,ROW(A45),FALSE)),"") | J47: =IF($K47+$L47=0,"N/A",$K47/($K47+$L47)) | K47: =COUNTIF($F47:$G47,"양호") | L47: =COUNTIF($F47:$G47,"취약") | M47: =COUNTIF($F47:$G47,"N/A")
C48: W-43 | D48: 이벤트 로그 파일 접근 통제 설정 | E48: 중 | F48: =IFERROR(T(HLOOKUP(F$3,'3-1. 진단 결과(window)'!$F$3:$I$69,ROW(A46),FALSE)),"") | G48: =IFERROR(T(HLOOKUP(G$3,'3-1. 진단 결과(window)'!$F$3:$I$69,ROW(A46),FALSE)),"") | J48: =IF($K48+$L48=0,"N/A",$K48/($K48+$L48)) | K48: =COUNTIF($F48:$G48,"양호") | L48: =COUNTIF($F48:$G48,"취약") | M48: =COUNTIF($F48:$G48,"N/A")
B49: 5. 보안 관리 | C49: W-44 | D49: 원격으로 액세스할 수 있는 레지스트리 경로 | E49: 상 | F49: =IFERROR(T(HLOOKUP(F$3,'3-1. 진단 결과(window)'!$F$3:$I$69,ROW(A47),FALSE)),"") | G49: =IFERROR(T(HLOOKUP(G$3,'3-1. 진단 결과(window)'!$F$3:$I$69,ROW(A47),FALSE)),"") | I49: =IF(COUNTIF(J49:J69,"N/A")=COUNTA(J49:J69),"N/A",AVERAGE(J49:J69)) | J49: =IF($K49+$L49=0,"N/A",$K49/($K49+$L49)) | K49: =COUNTIF($F49:$G49,"양호") | L49: =COUNTIF($F49:$G49,"취약") | M49: =COUNTIF($F49:$G49,"N/A")
C50: W-45 | D50: 백신 프로그램 설치 | E50: 상 | F50: =IFERROR(T(HLOOKUP(F$3,'3-1. 진단 결과(window)'!$F$3:$I$69,ROW(A48),FALSE)),"") | G50: =IFERROR(T(HLOOKUP(G$3,'3-1. 진단 결과(window)'!$F$3:$I$69,ROW(A48),FALSE)),"") | J50: =IF($K50+$L50=0,"N/A",$K50/($K50+$L50)) | K50: =COUNTIF($F50:$G50,"양호") | L50: =COUNTIF($F50:$G50,"취약") | M50: =COUNTIF($F50:$G50,"N/A")
...

Sheet 3-1. 진단 결과(window)
B2: Windows 서버 취약점 진단 상세결과(64항목)
B3: 진단항목 | C3: No. | D3: 세부 진단항목 | E3: 진단기준 | F3: 1 | G3: =IFERROR(VLOOKUP(F$3,'1. 진단 대상'!$B$5:$F$6,2,FALSE),"") | H3: 2 | I3: =IFERROR(VLOOKUP(H$3,'1. 진단 대상'!$B$5:$F$6,2,FALSE),"")
G4: =IFERROR(VLOOKUP(F$3,'1. 진단 대상'!$B$5:$F$6,3,FALSE),"") | I4: =IFERROR(VLOOKUP(H$3,'1. 진단 대상'!$B$5:$F$6,3,FALSE),"")
G5: =IFERROR(VLOOKUP(F$3,'1. 진단 대상'!$B$5:$F$6,5,FALSE),"") | I5: =IFERROR(VLOOKUP(H$3,'1. 진단 대상'!$B$5:$F$6,5,FALSE),"")
B6: 1. 계정 관리 | C6: W-01 | D6: Administrator 계정 이름 변경 등 보안성 강화 | E6: 양호 - Administrator 기본 계정 이름을 변경하거나 강화된 비밀번호를 적용한 경우 취약 - Administrator 기본 계정 이름을 변경하지 않거나 단순 비밀번호를 적용한 경우
C7: W-02 | D7: Guest 계정 비활성화 | E7: 양호 - Guest 계정이 비활성화되어 있는 경우 취약 - Guest 계정이 활성화되어 있는 경우
C8: W-03 | D8: 불필요한 계정 제거 | E8: 양호 - 불필요한 계정이 존재하지 않는 경우 취약 - 불필요한 계정이 존재하는 경우
C9: W-04 | D9: 계정 잠금 임계값 설정 | E9: 양호 - 계정 잠금 임계값이 5 이하의 값으로 설정된 경우 취약 - 계정 잠금 임계값이 5 초과의 값으로 설정된 경우
C10: W-05 | D10: 해독 가능한 암호화를 사용하여 암호 저장 해제 | E10: 양호 - “해독 가능한 암호화를 사용하여 암호 저장” 정책이 “사용 안 함”으로 설정된 경우 취약 - “해독 가능한 암호화를 사용하여 암호 저장” 정책이 “사용”으로 설정된 경우
C11: W-06 | D11: 관리자 그룹에 최소한의 사용자 포함 | E11: 양호 - Administrators 그룹의 구성원을 1명 이하로 유지하거나, 불필요한 관리자 계정이 존재하지 않는 경우 취약 - Administrators 그룹에 불필요한 관리자 계정이 존재하는 경우
C12: W-07 | D12: Everyone 사용 권한을 익명 사용자에게 적용 | E12: 양호 - “Everyone 사용 권한을 익명 사용자에게 적용” 정책이 “사용 안 함”으로 되어 있는 경우 취약 - “Everyone 사용 권한을 익명 사용자에게 적용” 정책이 “사용”으로 되어 있는 경우
C13: W-08 | D13: 계정 잠금 기간 설정 | E13: 양호 - “계정 잠금 기간” 및 “계정 잠금 기간 원래대로 설정 기간”이 60분 이상으로 설정된 경우 취약 - “계정 잠금 기간” 및 “잠금 기간 원래대로 설정 기간”이 설정되지 않거나 60분 미만으로 설정된 경우
C14: W-09 | D14: 비밀번호 관리정책 설정 | E14: 양호 - 계정 비밀번호 관리 정책이 모두 적용된 경우 취약 - 계정 비밀번호 관리 정책이 모두 적용되어 있지 않은 경우
C15: W-10 | D15: 마지막 사용자 이름 표시 안 함 | E15: 양호 - “마지막 사용자 이름 표시 안 함”이 “사용”으로 설정된 경우 취약 - “마지막 사용자 이름 표시 안 함”이 “사용 안 함”으로 설정된 경우
C16: W-11 | D16: 로컬 로그온 허용 | E16: 양호 - 로컬 로그온 허용 정책에 Administrators, IUSR_ 만 존재하는 경우 취약 - 로컬 로그온 허용 정책에 Administrators, IUSR_ 외 다른 계정 및 그룹이 존재하는 경우
C17: W-12 | D17: 익명 SID/이름 변환 허용 해제 | E17: 양호 - “익명 SID/이름 변환 허용” 정책이 “사용 안 함”으로 설정된 경우 취약 - “익명 SID/이름 변환 허용” 정책이 “사용”으로 설정된 경우
C18: W-13 | D18: 콘솔 로그온 시 로컬 계정에서 빈 암호 사용 제한 | E18: 양호 - “콘솔 로그온 시 로컬 계정에서 빈 암호 사용 제한” 정책이 “사용”인 경우 취약 - “콘솔 로그온 시 로컬 계정에서 빈 암호 사용 제한” 정책이 “사용 안 함”인 경우
C19: W-14 | D19: 원격터미널 접속 가능한 사용자 그룹 제한 | E19: 양호 - (관리자 계정을 제외한) 원격 접속이 가능한 계정을 생성하여 타 사용자의 원격 접속을 제한하고, 원격 접속 사용자 그룹에 불필요한 계정이 등록되어 있지 않은 경우 취약 - (관리자 계정을 제외한) 원격 접속이 가능한 별도의 계정이 존재하지 않는 경우
B20: 2. 서비스 관리 | C20: W-15 | D20: 사용자 개인키 사용 시 암호 입력 | E20: 양호 - 사용자 개인 키를 사용할 때마다 암호 입력을 받는 경우 취약 - 사용자 개인 키를 사용할 때마다 암호 입력을 받지 않는 경우
C21: W-16 | D21: 공유 권한 및 사용자 그룹 설정 | E21: 양호 : 일반 공유 디렉터리가 없거나 공유 디렉터리 접근 권한에 Everyone 권한이 없는 경우 취약 : 일반 공유 디렉터리의 접근 권한에 Everyone 권한이 있는 경우
C22: W-17 | D22: 하드디스크 기본 공유 제거 | E22: 양호 - 레지스트리의 AutoShareServer (WinNT: AutoShareWks)가 0이며 기본 공유가 존재하지 않는 경우 취약 - 레지스트리의 AutoShareServer (WinNT: AutoShareWks)가 1이거나 기본 공유가 존재하는 경우
C23: W-18 | D23: 불필요한 서비스 제거 | E23: 양호 - 일반적으로 불필요한 서비스(아래 목록 참조)가 중지된 경우 취약 - 일반적으로 불필요한 서비스(아래 목록 참조)가 구동 중인 경우
C24: W-19 | D24: 불필요한 IIS 서비스 구동 점검 | E24: 양호 - IIS 서비스를 사용하지 않는 경우 또는 필요에 의해 IIS 서비스를 사용하는 경우 취약 - IIS 서비스를 불필요하게 사용하는 경우
C25: W-20 | D25: NetBIOS 바인딩 서비스 구동 점검 | E25: 양호 - TCP/IP와 NetBIOS 간의 바인딩이 제거되어 있는 경우 취약 - TCP/IP와 NetBIOS 간의 바인딩이 제거되어 있지 않은 경우
C26: W-21 | D26: 암호화되지 않는 FTP 서비스 비활성화 | E26: 양호 - FTP 서비스를 사용하지 않는 경우 또는 Secure FTP 서비스를 사용하는 경우 취약 - 암호화되지 않는 FTP 서비스를 사용하는 경우
C27: W-22 | D27: FTP 디렉토리 접근권한 설정 | E27: 양호 - FTP 홈 디렉터리에 Everyone 권한이 없는 경우 취약 - FTP 홈 디렉터리에 Everyone 권한이 있는 경우
C28: W-23 | D28: 공유 서비스에 대한 익명 접근 제한 설정 | E28: 양호 - 공유 서비스를 사용하지 않거나, 익명 인증 사용 안 함으로 설정된 경우 취약 - 공유 서비스를 사용하거나, 익명 인증 사용함으로 설정된 경우
C29: W-24 | D29: FTP 접근 제어 설정 | E29: 양호 - 특정 IP주소에서만 FTP 서버에 접속하도록 접근 제어 설정을 적용한 경우 취약 - 특정 IP주소에서만 FTP 서버에 접속하도록 접근 제어 설정을 적용하지 않는 경우 ※ 조치 시 마스터 속성과 모든 사이트에 적용함
C30: W-25 | D30: DNS Zone Transfer 설정 | E30: 양호 - 아래 기준에 해당하는 경우 1. DNS 서비스가 비활성화인 경우 2. 영역 전송 허용을 하지 않는 경우 3. 특정 서버로만 설정이 되어있는 경우 취약 - 위 3개 기준 중 하나라도 해당하지 않는 경우
C31: W-26 | D31: RDS(Remote Data Services) 제거 | E31: 양호 - 다음 중 한 가지라도 해당하는 경우 1. IIS를 사용하지 않는 경우 2. Windows 2008 이상 버전을 사용하는 경우 3. Windows 2000 서비스팩 4, Windows 2003 서비스팩 2 이상 설치된 경우 4. 기본 웹 사이트에 MSADC 가상 디렉터리가 존재하지 않는 경우 5. 해당 레지스트리 값이 존재하지 않는 경우 취약 - 양호 기준에 한 가지도 해당하지 않는 경우
C32: W-27 | D32: 최신 Windows OS Build 버전 적용 | E32: 양호 - 최신 Build가 설치되어 있으며 적용 절차 및 방법이 수립된 경우 취약 - 최신 Build가 설치되지 않거나, 적용 절차 및 방법이 수립되지 않은 경우
... C42: W-37 | D42: 예약된 작업에 의심스러운 명령이 등록되어 있는지 점검 | E42: 양호 : 불필요한 명령어나 파일 등 주기적인 예약 작업의 존재 여부를 주기적으로 점검하고 제거한 경우 취약 : 불필요한 명령어나 파일 등 주기적인 예약 작업의 존재 여부를 주기적으로 점검하지 않거나, 불필 요한 작업을 제거하지 않은 경우
B43: 3. 패치 관리 | C43: W-38 | D43: 주기적 보안 패치 및 벤더 권고사항 적용 | E43: 양호 : 패치 절차를 수립하여 주기적으로 패치를 확인 및 설치하는 경우 취약 : 패치 절차가 수립되어 있지 않거나 주기적으로 패치를 설치하지 않는 경우
C44: W-39 | D44: 백신 프로그램 업데이트 | E44: 양호 : 바이러스 백신 프로그램의 최신 엔진 업데이트가 설치되어 있거나, 망 격리 환경의 경우 백신 업데이트를 위한 절차 및 적용 방법이 수립된 경우 취약 : 바이러스 백신 프로그램의 최신 엔진 업데이트가 설치되어 있지 않거나, 망 격리 환경의 경우 백신 업데이트를 위한 절차 및 적용 방법이 수립되지 않은 경우
B45: 4. 로그 관리 | C45: W-40 | D45: 정책에 따른 시스템 로깅 설정 | E45: 양호 : 감사 정책 권고 기준에 따라 감사 설정이 되어 있는 경우 취약 : 감사 정책 권고 기준에 따라 감사 설정이 되어 있지 않은 경우
C46: W-41 | D46: NTP 및 시각 동기화 설정 | E46: 양호 : NTP 및 시각 동기화를 설정한 경우 취약 : NTP 및 시각 동기화를 설정하지 않은 경우
C47: W-42 | D47: 이벤트 로그 관리 설정 | E47: 양호 : 최대 로그 크기 “10,240KB 이상”으로 설정, “90일 이후 이벤트 덮어씀”을 설정한 경우 취약 : 최대 로그 크기 “10,240KB 미만”으로 설정, 이벤트 덮어씀 기간이 “90일 이하로 설정된 경우
C48: W-43 | D48: 이벤트 로그 파일 접근 통제 설정 | E48: 양호 : 로그 디렉터리의 접근 권한에 Everyone 권한이 없는 경우 취약 : 로그 디렉터리의 접근 권한에 Everyone 권한이 있는 경우
B49: 5. 보안 관리 | C49: W-44 | D49: 원격으로 액세스할 수 있는 레지스트리 경로 | E49: 양호 - Remote Registry Service가 중지된 경우 취약 - Remote Registry Service가 사용 중인 경우
C50: W-45 | D50: 백신 프로그램 설치 | E50: 양호 - 바이러스 백신 프로그램이 설치된 경우 취약 - 바이러스 백신 프로그램이 설치되어 있지 않은 경우
...
